05/27/2024 09:28:10 - INFO - __main__ - ***** Running training *****
05/27/2024 09:28:10 - INFO - __main__ -   Num examples = 28000
05/27/2024 09:28:10 - INFO - __main__ -   Num Epochs = 2000
05/27/2024 09:28:10 - INFO - __main__ -   Instantaneous batch size per device = 8
05/27/2024 09:28:10 - INFO - __main__ -   Total train batch size (w. parallel, distributed & accumulation) = 8
05/27/2024 09:28:11 - INFO - __main__ -   Gradient Accumulation steps = 1
05/27/2024 09:28:11 - INFO - __main__ -   Total optimization steps = 7000000
05/27/2024 09:28:11 - INFO - __main__ -   Image path = ddpm-model-mattymchen/celeba-hq-64/Local-celeba-hq-2000-1000-0-b_bar/generated_images
Traceback (most recent call last):
  File "/snap/pycharm-professional/384/plugins/python/helpers/pydev/pydevd.py", line 1535, in _exec
    pydev_imports.execfile(file, globals, locals)  # execute the script
  File "/snap/pycharm-professional/384/plugins/python/helpers/pydev/_pydev_imps/_pydev_execfile.py", line 18, in execfile
    exec(compile(contents+"\n", file, 'exec'), glob, loc)
  File "/home/srk1995/PycharmProjects/diffusers/examples/unconditional_image_generation/train_local_unconditional.py", line 819, in <module>
    main(args)
  File "/home/srk1995/PycharmProjects/diffusers/examples/unconditional_image_generation/train_local_unconditional.py", line 616, in main
    accelerator.load_state(os.path.join(args.output_dir, path))
  File "/home/srk1995/anaconda3/envs/ADM/lib/python3.8/site-packages/accelerate/accelerator.py", line 2907, in load_state
    raise ValueError(f"Tried to find {input_dir} but folder does not exist")
ValueError: Tried to find ddpm-model-mattymchen/celeba-hq-64/Local-celeba-hq-2000-1000-0-b_bar/checkpoint-10 but folder does not exist
Resuming from checkpoint checkpoint-10